data/sample_binance_depth.ndjson
{"lastUpdateId":160000001,"bids":[["42150.00","1.50000000"],["42149.50","2.00000000"],["42149.00","0.80000000"],["42148.50","3.20000000"],["42148.00","1.10000000"]],"asks":[["42151.00","0.90000000"],["42151.50","1.20000000"],["42152.00","2.10000000"],["42152.50","0.60000000"],["42153.00","1.80000000"]]}
{"lastUpdateId":160000002,"bids":[["42150.00","1.80000000"],["42149.50","2.00000000"],["42149.00","0.80000000"]],"asks":[["42151.00","1.10000000"],["42151.50","1.20000000"]]}
{"lastUpdateId":160000003,"bids":[["42150.50","0.50000000"],["42150.00","1.80000000"]],"asks":[["42150.50","0.30000000"]]}
{"lastUpdateId":160000004,"bids":[["42150.50","0.00000000"]],"asks":[["42150.50","0.00000000"]]}
{"lastUpdateId":160000005,"bids":[["42151.00","2.10000000"]],"asks":[["42151.50","0.80000000"]]}
