data/sample_coinbase_l2.ndjson
{"type":"snapshot","product_id":"BTC-USD","bids":[["42150.00","1.5"],["42149.50","2.0"],["42149.00","0.8"],["42148.50","3.2"],["42148.00","1.1"],["42147.50","0.5"],["42147.00","2.8"],["42146.50","1.9"],["42146.00","0.7"],["42145.50","4.2"]],"asks":[["42151.00","0.9"],["42151.50","1.2"],["42152.00","2.1"],["42152.50","0.6"],["42153.00","1.8"],["42153.50","3.0"],["42154.00","0.4"],["42154.50","2.5"],["42155.00","1.3"],["42155.50","0.8"]]}
{"type":"l2update","product_id":"BTC-USD","time":"2024-01-15T10:30:00.001Z","changes":[["buy","42150.00","1.8"]]}
{"type":"l2update","product_id":"BTC-USD","time":"2024-01-15T10:30:00.002Z","changes":[["sell","42151.00","1.1"]]}
{"type":"l2update","product_id":"BTC-USD","time":"2024-01-15T10:30:00.003Z","changes":[["buy","42150.50","0.5"]]}
{"type":"l2update","product_id":"BTC-USD","time":"2024-01-15T10:30:00.004Z","changes":[["sell","42150.50","0.3"]]}
{"type":"match","product_id":"BTC-USD","time":"2024-01-15T10:30:00.005Z","side":"buy","price":"42150.50","size":"0.3"}
{"type":"l2update","product_id":"BTC-USD","time":"2024-01-15T10:30:00.006Z","changes":[["buy","42150.50","0.0"]]}
{"type":"l2update","product_id":"BTC-USD","time":"2024-01-15T10:30:00.007Z","changes":[["buy","42151.00","2.1"]]}
{"type":"l2update","product_id":"BTC-USD","time":"2024-01-15T10:30:00.008Z","changes":[["sell","42151.50","0.8"]]}
{"type":"l2update","product_id":"BTC-USD","time":"2024-01-15T10:30:00.009Z","changes":[["buy","42149.00","1.5"]]}
{"type":"l2update","product_id":"BTC-USD","time":"2024-01-15T10:30:00.010Z","changes":[["sell","42152.00","2.5"]]}
{"type":"match","product_id":"BTC-USD","time":"2024-01-15T10:30:00.011Z","side":"sell","price":"42151.00","size":"0.5"}
{"type":"l2update","product_id":"BTC-USD","time":"2024-01-15T10:30:00.012Z","changes":[["sell","42151.00","0.6"]]}
{"type":"l2update","product_id":"BTC-USD","time":"2024-01-15T10:30:00.013Z","changes":[["buy","42150.00","2.2"]]}
{"type":"l2update","product_id":"BTC-USD","time":"2024-01-15T10:30:00.014Z","changes":[["sell","42151.00","0.9"]]}
{"type":"l2update","product_id":"BTC-USD","time":"2024-01-15T10:30:00.015Z","changes":[["buy","42149.50","2.8"]]}
{"type":"l2update","product_id":"BTC-USD","time":"2024-01-15T10:30:00.016Z","changes":[["sell","42152.50","1.2"]]}
{"type":"l2update","product_id":"BTC-USD","time":"2024-01-15T10:30:00.017Z","changes":[["buy","42148.00","3.5"]]}
{"type":"l2update","product_id":"BTC-USD","time":"2024-01-15T10:30:00.018Z","changes":[["sell","42153.00","2.2"]]}
{"type":"match","product_id":"BTC-USD","time":"2024-01-15T10:30:00.019Z","side":"buy","price":"42151.00","size":"0.4"}
{"type":"l2update","product_id":"BTC-USD","time":"2024-01-15T10:30:00.020Z","changes":[["sell","42151.00","0.5"]]}
